Workbook

Sheet Linhas Investimento
A1: AGÊNCIA DE FOMENTO DE GOIÁS S/A | AA1: 2 | AB1: 2
A2: IMPORTANTE: Os valores simulados podem variar e estão sujeitos à data de vencimento da parcela e da liberação do crédito; O financiamento e condições são sujeitas à aprovação final da análise de crédito; Valores calculados com base na taxa líquida para quando não há atraso nos pagamentos.
A3: LINHA DE INVESTIMENTO | AA3: TAC | AB3: IOF
A4: LINHA | J4: 7 | K4: 1 | N4: LINHA | O4: TAXA (a.m.) | P4: TAXA BONUS | Q4: CG1 (a.m.) | R4: CG2 (a.m.) | S4: PRAZO (meses) | T4: CARÊNCIA (até meses) | U4: LIMITE | V4: GARANTIA | AA4: Descontado | AB4: Descontado
N5: GoiásFomento Investimento | O5: 0.0217 | P5: 0.0174 | Q5: =P5 -> 0.0174 | R5: =Q5 -> 0.0174 | S5: 60 | T5: 12 | U5: 400000 | V5: Sim | AA5: Financiado | AB5: Financiado
C6: =IF(AND(J4=1,K4=1),Q5,IF(AND(J4=1,K4=2),R5,IF(AND(J4=1,K4=3),P5,"-"))) -> - | N6: GoiásFomento Investimento VIP | O6: 0.0213 | P6: 0.017 | Q6: =P6 -> 0.017 | R6: =Q6 -> 0.017 | S6: 60 | T6: 12 | U6: 400000 | V6: Não
C7: =IF(AND(J4=2,K4=1),Q6,IF(AND(J4=2,K4=2),R6,IF(AND(J4=2,K4=3),P6,"-"))) -> - | N7: GoiásFomento Investimento - IMCF | O7: 0.0209 | P7: 0.0167 | Q7: =P7 -> 0.0167 | R7: =Q7 -> 0.0167 | S7: 60 | T7: 12 | U7: 400000
C8: =IF(AND(J4=3,K4=1),Q7,IF(AND(J4=3,K4=2),R7,IF(AND(J4=3,K4=3),P7,"-"))) -> - | N8: Goiás Fomento Investimento - VIP IMCF | O8: 0.0206 | P8: 0.0165 | Q8: =P8 -> 0.0165 | R8: =Q8 -> 0.0165 | S8: 60 | T8: 12 | U8: 400000
C9: =IF(AND(J4=4,K4=1),Q8,IF(AND(J4=4,K4=2),R8,IF(AND(J4=4,K4=3),P8,"-"))) -> - | N9: GoiásFomento Eficiência Energética (fixo) | O9: 0.0206 | P9: 0.0165 | Q9: =P9 -> 0.0165 | R9: =Q9 -> 0.0165 | S9: 60 | T9: 6 | U9: 400000
C10: =IF(AND(J4=5,K4=1),Q9,IF(AND(J4=5,K4=2),R9,IF(AND(J4=5,K4=3),P9,"-"))) -> - | N10: GoiásFomento Eficiência Energética MEI (fixo) | O10: 0.0206 | P10: 0.0165 | Q10: =P10 -> 0.0165 | R10: =R9 -> 0.0165 | S10: 60 | T10: 6 | U10: 30000
C11: =IF(AND(J4=6,K4=1),Q10,IF(AND(J4=6,K4=2),R10,IF(AND(J4=6,K4=3),P10,"-"))) -> - | N11: GoiásFomento (INVESTIMENTO)Tecnologia/PQF-IEL/Turismo/FarmaDrogas/ Contabilistas / Mulher Empreendedora | O11: 0.0206 | P11: 0.0165 | Q11: =P11 -> 0.0165 | R11: =Q11 -> 0.0165 | S11: 60 | T11: 12 | U11: 400000
C12: =IF(AND(J4=7,K4=1),Q11,IF(AND(J4=7,K4=2),R11,IF(AND(J4=7,K4=3),P11,"-"))) -> 0.0165 | N12: GoiásFomento Microcrédito Produtivo - Investimento | O12: 0.0206 | P12: 0.0165 | Q12: =P12 -> 0.0165 | R12: =Q12 -> 0.0165 | S12: 36 | T12: 12 | U12: 21000
C13: =IF(AND(J4=8,K4=1),Q12,IF(AND(J4=8,K4=2),R12,IF(AND(J4=8,K4=3),P12,"-"))) -> -
A14: INFORMAÇÕES | AK14: TAC | AL14: =F15 -> 2000 | AM14: =AL14/AL16 -> 0.033591696
A15: VALOR FINANCIADO | B15: 100000 | C15: TAXA NOMINAL | D15: =IF(J4=1,O5,IF(J4=2,O6,IF(J4=3,O7,IF(J4=4,O8,IF(J4=5,O9,IF(J4=6,O10,IF(J4=7,O11,IF(J4=8,O12)))))))) -> 0.0206 | E15: =AJ22 -> 0.017859866 | F15: =IF(B15<=3000,50,IF(B15<=21000,IF(B15*0.03<=420,B15*0.03,420),IF(B15<=100000,B15*0.02,2000+B15*0.005))) -> 2000 | J15: 4 | AK15: JUROS | AL15: =C22 -> 57538.523 | AM15: =AL15/AL16 -> 0.9664083
A16: CARÊNCIA | B16: 6 | C16: TAXA COM BÔNUS | D16: =LARGE(C6:C13,1) -> 0.0165 | F16: =AF24 -> 1507.5 | J16: 2 | AK16: TOTAL | AL16: =SUM(AL14:AL15) -> 59538.523
A17: PRAZO TOTAL | B17: 60 | C17: DATA DA PROPOSTA | D17: =TODAY() -> 46240 | F17: =IF(J21=TRUE,IF(K4=1,(B15*E19*0.001*B17),IF(K4=2,(F19*0.001*B17),IF(K4=3,0,""))),0) -> 0 | J17: Descontado | L17: FALSE | AJ17: 100000
A18: OPÇÕES DE GARANTIA | J18: Financiado | AJ18: =AJ22 -> 0.017859866 | AL18: =PMT(AJ18,AJ19,-AJ17) -> 2729.6846
A19: RENDA PARA AVAL | B19: =IF(LARGE(F23:F241,1)*3<2424,2424,LARGE(F23:F241,1)*3) -> 10679.177 | C19: ALIENAÇÃO DE IMÓVEL | D19: =IF(J21=TRUE,(B15-F19)*1.5/0.7,B15*1.5/0.7) -> 214285.71 | E19: 0.8 | F19: =IF(J21=TRUE,IF(K4=1,(B15*E19),IF(K4=2,B15*E19,IF(K4=3,0,""))),0) -> 0 | J19: FINANCIADO | L19: TRUE | AJ19: =B17 -> 60
A20: SIMULAÇÃO DO VALOR DAS PARCELAS | J20: Financiado
A21: PARCELA | B21: AMORTIZAÇÃO | C21: JUROS | D21: VALOR AMORTIZAÇÃO | E21: SALDO DEVEDOR | F21: PARCELA COM BÔNUS | J21: FALSE | AB21: IOF - ACIMA ATÉ 365 DIAS | AJ21: TIR (PARCELA C/ BÔNUS) | AK21: TIR (PARCELA S/ BÔNUS)
A22: TOTAL | C22: =SUM(C23:C242) -> 57538.523 | D22: =SUM(D23:D242) -> 103117.78 | F22: =SUM(F23:F242) -> 160656.28 | AJ22: =IRR(AJ23:AJ107) -> 0.017859866 | AK22: =IRR(AK23:AK107) -> 0.022073317
A23: 0 | C23: =D16 -> 0.0165 | E23: =IF(AND(AA1=1,AB1=1,J16=1),B15,IF(AND(AA1=1,AB1=1,J16=2),B15+F17,IF(AND(AA1=1,AB1=2,J16=1),B15+F16,IF(AND(AA1=1,AB1=2,J16=3),B15+F16,IF(AND(AA1=2,AB1=1,J16=1),B15+F15,IF(AND(AA1=2,AB1=1,J16=2),B15+F15+F17,IF(AND(AA1=2,AB1=2,J16=2),B15+F17+F16+F15,IF(AND(AA1=2,AB1=2,J16=3),B15+F15+F16,IF(AND(AA1=2,AB1=2,J16=1),B15+F15+F16,IF(AND(AA1=1,AB1=2,J16=2),B15+F16+F17, IF(AND(AA1=1,AB1=1,J16=3),B15))))))))))) -> 103507.5 | AJ23: =-B15 -> -100000 | AK23: =AJ23 -> -100000
A24: =IF(A23<B$17,A23+1,"") -> 1 | B24: =IF(A24="","",IF(A24<=B$16,"carência","amortização")) -> carência | C24: =IF(B24="","",E23*$C$23) -> 1707.8737 | D24: =IF(C24="","",IF(A24<=B$16,0,B$15/(B$17-B$16))) -> 0 | E24: =IF(F24="","",E23-D24) -> 103507.5 | F24: =IF(D24="","",D24+C24) -> 1707.8737 | AB24: IOF | AC24: 0.0038 | AE24: =AC27*AC24 -> 380 | AF24: =IF(L19=FALSE,0,IF(AND(AH25=TRUE,B15<=30000),AE24+AE26,AE24+AE25)) -> 1507.5 | AJ24: =IF(A24<=$B$17,F24,0) -> 1707.8737 | AK24: =IF(A24<=$B$17,E23*$D$15+D24,0) -> 2132.2545
A25: =IF(A24<B$17,A24+1,"") -> 2 | B25: =IF(A25="","",IF(A25<=B$16,"carência","amortização")) -> carência | C25: =IF(B25="","",E24*$C$23) -> 1707.8737 | D25: =IF(C25="","",IF(A25<=B$16,0,B$15/(B$17-B$16))) -> 0 | E25: =IF(F25="","",E24-D25) -> 103507.5 | F25: =IF(D25="","",D25+C25) -> 1707.8737 | AB25: ALÍQUOTA | AC25: 4.1e-05 | AE25: =SUM(AG30:AG83) -> 1127.5 | AH25: FALSE | AJ25: =IF(A25<=$B$17,F25,0) -> 1707.8737 | AK25: =IF(A25<=$B$17,E24*$D$15+D25,0) -> 2132.2545
A26: =IF(A25<B$17,A25+1,"") -> 3 | B26: =IF(A26="","",IF(A26<=B$16,"carência","amortização")) -> carência | C26: =IF(B26="","",E25*$C$23) -> 1707.8737 | D26: =IF(C26="","",IF(A26<=B$16,0,B$15/(B$17-B$16))) -> 0 | E26: =IF(F26="","",E25-D26) -> 103507.5 | F26: =IF(D26="","",D26+C26) -> 1707.8737 | AB26: ALÍQUOTA SIMPLES | AC26: =0.00137/100 -> 1.37e-05 | AE26: =SUM(AH30:AH308) -> 376.75 | AJ26: =IF(A26<=$B$17,F26,0) -> 1707.8737 | AK26: =IF(A26<=$B$17,E25*$D$15+D26,0) -> 2132.2545
A27: =IF(A26<B$17,A26+1,"") -> 4 | B27: =IF(A27="","",IF(A27<=B$16,"carência","amortização")) -> carência | C27: =IF(B27="","",E26*$C$23) -> 1707.8737 | D27: =IF(C27="","",IF(A27<=B$16,0,B$15/(B$17-B$16))) -> 0 | E27: =IF(F27="","",E26-D27) -> 103507.5 | F27: =IF(D27="","",D27+C27) -> 1707.8737 | AB27: LIBERAÇÃO | AC27: =B15 -> 100000 | AJ27: =IF(A27<=$B$17,F27,0) -> 1707.8737 | AK27: =IF(A27<=$B$17,E26*$D$15+D27,0) -> 2132.2545
A28: =IF(A27<B$17,A27+1,"") -> 5 | B28: =IF(A28="","",IF(A28<=B$16,"carência","amortização")) -> carência | C28: =IF(B28="","",E27*$C$23) -> 1707.8737 | D28: =IF(C28="","",IF(A28<=B$16,0,B$15/(B$17-B$16))) -> 0 | E28: =IF(F28="","",E27-D28) -> 103507.5 | F28: =IF(D28="","",D28+C28) -> 1707.8737 | AG28: IOF NORMAL | AH28: IOF SIMPLES | AJ28: =IF(A28<=$B$17,F28,0) -> 1707.8737 | AK28: =IF(A28<=$B$17,E27*$D$15+D28,0) -> 2132.2545
A29: =IF(A28<B$17,A28+1,"") -> 6 | B29: =IF(A29="","",IF(A29<=B$16,"carência","amortização")) -> carência | C29: =IF(B29="","",E28*$C$23) -> 1707.8737 | D29: =IF(C29="","",IF(A29<=B$16,0,B$15/(B$17-B$16))) -> 0 | E29: =IF(F29="","",E28-D29) -> 103507.5 | F29: =IF(D29="","",D29+C29) -> 1707.8737 | AA29: 0 | AB29: =D17 -> 46240 | AC29: =IF(AB29="","",AC27) -> 100000 | AD29: =IF(AA29="","",IF(AA29<=B$16,0,B$15/(B$17-B$16))) -> 0 | AJ29: =IF(A29<=$B$17,F29,0) -> 1707.8737 | AK29: =IF(A29<=$B$17,E28*$D$15+D29,0) -> 2132.2545
A30: =IF(A29<B$17,A29+1,"") -> 7 | B30: =IF(A30="","",IF(A30<=B$16,"carência","amortização")) -> amortização | C30: =IF(B30="","",E29*$C$23) -> 1707.8737 | D30: =IF(C30="","",IF(A30<=B$16,0,B$15/(B$17-B$16))) -> 1851.8519 | E30: =IF(F30="","",E29-D30) -> 101655.65 | F30: =IF(D30="","",D30+C30) -> 3559.7256 | AA30: =IF(AA29<B$17,AA29+1,"") -> 1 | AB30: =IF(AA30="","",AB29+30) -> 46270 | AC30: =IF(AB30="","",IF(AA30<=B$16,AC29,AC29-AD30)) -> 100000 | AD30: =IF(AA30="","",IF(AA30<=B$16,0,B$15/(B$17-B$16))) -> 0 | AE30: =IF(AD30="","",AB30-AB29) -> 30 | AF30: =IF(AE30="","",AB30-AB$29) -> 30 | AG30: =IF(AF30="","",IF(AF30<365,AF30*AC$25*AD30,365*AD30*AC$25)) -> 0 | AH30: =IF(AF30="","",IF(AF30<365,AF30*AC$26*AD30,365*AD30*AC$26)) -> 0 | AJ30: =IF(A30<=$B$17,F30,0) -> 3559.7256 | AK30: =IF(A30<=$B$17,E29*$D$15+D30,0) -> 3984.1064
A31: =IF(A30<B$17,A30+1,"") -> 8 | B31: =IF(A31="","",IF(A31<=B$16,"carência","amortização")) -> amortização | C31: =IF(B31="","",E30*$C$23) -> 1677.3182 | D31: =IF(C31="","",IF(A31<=B$16,0,B$15/(B$17-B$16))) -> 1851.8519 | E31: =IF(F31="","",E30-D31) -> 99803.796 | F31: =IF(D31="","",D31+C31) -> 3529.17 | AA31: =IF(AA30<B$17,AA30+1,"") -> 2 | AB31: =IF(AA31="","",AB30+30) -> 46300 | AC31: =IF(AB31="","",IF(AA31<=B$16,AC30,AC30-AD31)) -> 100000 | AD31: =IF(AA31="","",IF(AA31<=B$16,0,B$15/(B$17-B$16))) -> 0 | AE31: =IF(AD31="","",AB31-AB30) -> 30 | AF31: =IF(AE31="","",AB31-AB$29) -> 60 | AG31: =IF(AF31="","",IF(AF31<365,AF31*AC$25*AD31,365*AD31*AC$25)) -> 0 | AH31: =IF(AF31="","",IF(AF31<365,AF31*AC$26*AD31,365*AD31*AC$26)) -> 0 | AJ31: =IF(A31<=$B$17,F31,0) -> 3529.17 | AK31: =IF(A31<=$B$17,E30*$D$15+D31,0) -> 3945.9582
A32: =IF(A31<B$17,A31+1,"") -> 9 | B32: =IF(A32="","",IF(A32<=B$16,"carência","amortização")) -> amortização | C32: =IF(B32="","",E31*$C$23) -> 1646.7626 | D32: =IF(C32="","",IF(A32<=B$16,0,B$15/(B$17-B$16))) -> 1851.8519 | E32: =IF(F32="","",E31-D32) -> 97951.944 | F32: =IF(D32="","",D32+C32) -> 3498.6145 | AA32: =IF(AA31<B$17,AA31+1,"") -> 3 | AB32: =IF(AA32="","",AB31+30) -> 46330 | AC32: =IF(AB32="","",IF(AA32<=B$16,AC31,AC31-AD32)) -> 100000 | AD32: =IF(AA32="","",IF(AA32<=B$16,0,B$15/(B$17-B$16))) -> 0 | AE32: =IF(AD32="","",AB32-AB31) -> 30 | AF32: =IF(AE32="","",AB32-AB$29) -> 90 | AG32: =IF(AF32="","",IF(AF32<365,AF32*AC$25*AD32,365*AD32*AC$25)) -> 0 | AH32: =IF(AF32="","",IF(AF32<365,AF32*AC$26*AD32,365*AD32*AC$26)) -> 0 | AJ32: =IF(A32<=$B$17,F32,0) -> 3498.6145 | AK32: =IF(A32<=$B$17,E31*$D$15+D32,0) -> 3907.8101
A33: =IF(A32<B$17,A32+1,"") -> 10 | B33: =IF(A33="","",IF(A33<=B$16,"carência","amortização")) -> amortização | C33: =IF(B33="","",E32*$C$23) -> 1616.2071 | D33: =IF(C33="","",IF(A33<=B$16,0,B$15/(B$17-B$16))) -> 1851.8519 | E33: =IF(F33="","",E32-D33) -> 96100.093 | F33: =IF(D33="","",D33+C33) -> 3468.0589 | AA33: =IF(AA32<B$17,AA32+1,"") -> 4 | AB33: =IF(AA33="","",AB32+30) -> 46360 | AC33: =IF(AB33="","",IF(AA33<=B$16,AC32,AC32-AD33)) -> 100000 | AD33: =IF(AA33="","",IF(AA33<=B$16,0,B$15/(B$17-B$16))) -> 0 | AE33: =IF(AD33="","",AB33-AB32) -> 30 | AF33: =IF(AE33="","",AB33-AB$29) -> 120 | AG33: =IF(AF33="","",IF(AF33<365,AF33*AC$25*AD33,365*AD33*AC$25)) -> 0 | AH33: =IF(AF33="","",IF(AF33<365,AF33*AC$26*AD33,365*AD33*AC$26)) -> 0 | AJ33: =IF(A33<=$B$17,F33,0) -> 3468.0589 | AK33: =IF(A33<=$B$17,E32*$D$15+D33,0) -> 3869.6619
A34: =IF(A33<B$17,A33+1,"") -> 11 | B34: =IF(A34="","",IF(A34<=B$16,"carência","amortização")) -> amortização | C34: =IF(B34="","",E33*$C$23) -> 1585.6515 | D34: =IF(C34="","",IF(A34<=B$16,0,B$15/(B$17-B$16))) -> 1851.8519 | E34: =IF(F34="","",E33-D34) -> 94248.241 | F34: =IF(D34="","",D34+C34) -> 3437.5034 | AA34: =IF(AA33<B$17,AA33+1,"") -> 5 | AB34: =IF(AA34="","",AB33+30) -> 46390 | AC34: =IF(AB34="","",IF(AA34<=B$16,AC33,AC33-AD34)) -> 100000 | AD34: =IF(AA34="","",IF(AA34<=B$16,0,B$15/(B$17-B$16))) -> 0 | AE34: =IF(AD34="","",AB34-AB33) -> 30 | AF34: =IF(AE34="","",AB34-AB$29) -> 150 | AG34: =IF(AF34="","",IF(AF34<365,AF34*AC$25*AD34,365*AD34*AC$25)) -> 0 | AH34: =IF(AF34="","",IF(AF34<365,AF34*AC$26*AD34,365*AD34*AC$26)) -> 0 | AJ34: =IF(A34<=$B$17,F34,0) -> 3437.5034 | AK34: =IF(A34<=$B$17,E33*$D$15+D34,0) -> 3831.5138
A35: =IF(A34<B$17,A34+1,"") -> 12 | B35: =IF(A35="","",IF(A35<=B$16,"carência","amortização")) -> amortização | C35: =IF(B35="","",E34*$C$23) -> 1555.096 | D35: =IF(C35="","",IF(A35<=B$16,0,B$15/(B$17-B$16))) -> 1851.8519 | E35: =IF(F35="","",E34-D35) -> 92396.389 | F35: =IF(D35="","",D35+C35) -> 3406.9478 | AA35: =IF(AA34<B$17,AA34+1,"") -> 6 | AB35: =IF(AA35="","",AB34+30) -> 46420 | AC35: =IF(AB35="","",IF(AA35<=B$16,AC34,AC34-AD35)) -> 100000 | AD35: =IF(AA35="","",IF(AA35<=B$16,0,B$15/(B$17-B$16))) -> 0 | AE35: =IF(AD35="","",AB35-AB34) -> 30 | AF35: =IF(AE35="","",AB35-AB$29) -> 180 | AG35: =IF(AF35="","",IF(AF35<365,AF35*AC$25*AD35,365*AD35*AC$25)) -> 0 | AH35: =IF(AF35="","",IF(AF35<365,AF35*AC$26*AD35,365*AD35*AC$26)) -> 0 | AJ35: =IF(A35<=$B$17,F35,0) -> 3406.9478 | AK35: =IF(A35<=$B$17,E34*$D$15+D35,0) -> 3793.3656
A36: =IF(A35<B$17,A35+1,"") -> 13 | B36: =IF(A36="","",IF(A36<=B$16,"carência","amortização")) -> amortização | C36: =IF(B36="","",E35*$C$23) -> 1524.5404 | D36: =IF(C36="","",IF(A36<=B$16,0,E$23/(B$17-B$16))) -> 1916.8056 | E36: =IF(F36="","",E35-D36) -> 90479.583 | F36: =IF(D36="","",D36+C36) -> 3441.346 | AA36: =IF(AA35<B$17,AA35+1,"") -> 7 | AB36: =IF(AA36="","",AB35+30) -> 46450 | AC36: =IF(AB36="","",IF(AA36<=B$16,AC35,AC35-AD36)) -> 98148.148 | AD36: =IF(AA36="","",IF(AA36<=B$16,0,B$15/(B$17-B$16))) -> 1851.8519 | AE36: =IF(AD36="","",AB36-AB35) -> 30 | AF36: =IF(AE36="","",AB36-AB$29) -> 210 | AG36: =IF(AF36="","",IF(AF36<365,AF36*AC$25*AD36,365*AD36*AC$25)) -> 15.944444 | AH36: =IF(AF36="","",IF(AF36<365,AF36*AC$26*AD36,365*AD36*AC$26)) -> 5.3277778 | AJ36: =IF(A36<=$B$17,F36,0) -> 3441.346 | AK36: =IF(A36<=$B$17,E35*$D$15+D36,0) -> 3820.1712
A37: =IF(A36<B$17,A36+1,"") -> 14 | B37: =IF(A37="","",IF(A37<=B$16,"carência","amortização")) -> amortização | C37: =IF(B37="","",E36*$C$23) -> 1492.9131 | D37: =IF(C37="","",IF(A37<=B$16,0,E$23/(B$17-B$16))) -> 1916.8056 | E37: =IF(F37="","",E36-D37) -> 88562.778 | F37: =IF(D37="","",D37+C37) -> 3409.7187 | AA37: =IF(AA36<B$17,AA36+1,"") -> 8 | AB37: =IF(AA37="","",AB36+30) -> 46480 | AC37: =IF(AB37="","",IF(AA37<=B$16,AC36,AC36-AD37)) -> 96296.296 | AD37: =IF(AA37="","",IF(AA37<=B$16,0,B$15/(B$17-B$16))) -> 1851.8519 | AE37: =IF(AD37="","",AB37-AB36) -> 30 | AF37: =IF(AE37="","",AB37-AB$29) -> 240 | AG37: =IF(AF37="","",IF(AF37<365,AF37*AC$25*AD37,365*AD37*AC$25)) -> 18.222222 | AH37: =IF(AF37="","",IF(AF37<365,AF37*AC$26*AD37,365*AD37*AC$26)) -> 6.0888889 | AJ37: =IF(A37<=$B$17,F37,0) -> 3409.7187 | AK37: =IF(A37<=$B$17,E36*$D$15+D37,0) -> 3780.685
A38: =IF(A37<B$17,A37+1,"") -> 15 | B38: =IF(A38="","",IF(A38<=B$16,"carência","amortização")) -> amortização | C38: =IF(B38="","",E37*$C$23) -> 1461.2858 | D38: =IF(C38="","",IF(A38<=B$16,0,E$23/(B$17-B$16))) -> 1916.8056 | E38: =IF(F38="","",E37-D38) -> 86645.972 | F38: =IF(D38="","",D38+C38) -> 3378.0914 | AA38: =IF(AA37<B$17,AA37+1,"") -> 9 | AB38: =IF(AA38="","",AB37+30) -> 46510 | AC38: =IF(AB38="","",IF(AA38<=B$16,AC37,AC37-AD38)) -> 94444.444 | AD38: =IF(AA38="","",IF(AA38<=B$16,0,B$15/(B$17-B$16))) -> 1851.8519 | AE38: =IF(AD38="","",AB38-AB37) -> 30 | AF38: =IF(AE38="","",AB38-AB$29) -> 270 | AG38: =IF(AF38="","",IF(AF38<365,AF38*AC$25*AD38,365*AD38*AC$25)) -> 20.5 | AH38: =IF(AF38="","",IF(AF38<365,AF38*AC$26*AD38,365*AD38*AC$26)) -> 6.85 | AJ38: =IF(A38<=$B$17,F38,0) -> 3378.0914 | AK38: =IF(A38<=$B$17,E37*$D$15+D38,0) -> 3741.1988
A39: =IF(A38<B$17,A38+1,"") -> 16 | B39: =IF(A39="","",IF(A39<=B$16,"carência","amortização")) -> amortização | C39: =IF(B39="","",E38*$C$23) -> 1429.6585 | D39: =IF(C39="","",IF(A39<=B$16,0,E$23/(B$17-B$16))) -> 1916.8056 | E39: =IF(F39="","",E38-D39) -> 84729.167 | F39: =IF(D39="","",D39+C39) -> 3346.4641 | AA39: =IF(AA38<B$17,AA38+1,"") -> 10 | AB39: =IF(AA39="","",AB38+30) -> 46540 | AC39: =IF(AB39="","",IF(AA39<=B$16,AC38,AC38-AD39)) -> 92592.593 | AD39: =IF(AA39="","",IF(AA39<=B$16,0,B$15/(B$17-B$16))) -> 1851.8519 | AE39: =IF(AD39="","",AB39-AB38) -> 30 | AF39: =IF(AE39="","",AB39-AB$29) -> 300 | AG39: =IF(AF39="","",IF(AF39<365,AF39*AC$25*AD39,365*AD39*AC$25)) -> 22.777778 | AH39: =IF(AF39="","",IF(AF39<365,AF39*AC$26*AD39,365*AD39*AC$26)) -> 7.6111111 | AJ39: =IF(A39<=$B$17,F39,0) -> 3346.4641 | AK39: =IF(A39<=$B$17,E38*$D$15+D39,0) -> 3701.7126
A40: =IF(A39<B$17,A39+1,"") -> 17 | B40: =IF(A40="","",IF(A40<=B$16,"carência","amortização")) -> amortização | C40: =IF(B40="","",E39*$C$23) -> 1398.0312 | D40: =IF(C40="","",IF(A40<=B$16,0,E$23/(B$17-B$16))) -> 1916.8056 | E40: =IF(F40="","",E39-D40) -> 82812.361 | F40: =IF(D40="","",D40+C40) -> 3314.8368 | AA40: =IF(AA39<B$17,AA39+1,"") -> 11 | AB40: =IF(AA40="","",AB39+30) -> 46570 | AC40: =IF(AB40="","",IF(AA40<=B$16,AC39,AC39-AD40)) -> 90740.741 | AD40: =IF(AA40="","",IF(AA40<=B$16,0,B$15/(B$17-B$16))) -> 1851.8519 | AE40: =IF(AD40="","",AB40-AB39) -> 30 | AF40: =IF(AE40="","",AB40-AB$29) -> 330 | AG40: =IF(AF40="","",IF(AF40<365,AF40*AC$25*AD40,365*AD40*AC$25)) -> 25.055556 | AH40: =IF(AF40="","",IF(AF40<365,AF40*AC$26*AD40,365*AD40*AC$26)) -> 8.3722222 | AJ40: =IF(A40<=$B$17,F40,0) -> 3314.8368 | AK40: =IF(A40<=$B$17,E39*$D$15+D40,0) -> 3662.2264
...

Sheet Linhas Giro Puro
A1: AGÊNCIA DE FOMENTO DE GOIÁS S/A | AA1: 2 | AB1: 2
A2: IMPORTANTE: Os valores simulados não possuem valor comercial. Diversos fatores interferem no cáculo final como taxas e serviços contratados. O financiamento e condições são sujeitas à aprovação final da análise de crédito; Valores calculados com base na taxa líquida (incluso o bônus por adimplência) quando não há atraso nos pagamentos.
A3: LINHA DE CAPITAL DE GIRO | AA3: TAC | AB3: IOF
A4: LINHA | J4: 6 | K4: 1 | N4: LINHA | O4: TAXA (a.m.) | P4: TAXA BONUS | Q4: CG1 (a.m.) | R4: CG2 (a.m.) | S4: PRAZO (meses) | T4: CARÊNCIA (até meses) | U4: LIMITE | V4: GARANTIA | AA4: Descontado | AB4: Descontado
N5: GoiásFomento Giro | O5: 2.27 | P5: 0 | Q5: 1.81 | R5: =Q5 -> 1.81 | S5: 24 | T5: 3 | U5: 300000 | V5: CG1 | AA5: Financiado | AB5: Financiado
C6: =IF(AND(J4=1,K4=1),Q5,IF(AND(J4=1,K4=2),R5,IF(AND(J4=1,K4=3),P5,"-"))) -> - | N6: GoiásFomento Giro VIP | O6: 2.19 | P6: 0 | Q6: 1.75 | R6: =Q6 -> 1.75 | S6: 36 | T6: 3 | U6: 300000 | V6: CG2
C7: =IF(AND(J4=2,K4=1),Q6,IF(AND(J4=2,K4=2),R6,IF(AND(J4=2,K4=3),P6,"-"))) -> - | N7: GoiásFomento Giro - IMCF | O7: 2.17 | P7: 0 | Q7: 1.74 | R7: =Q7 -> 1.74 | S7: 24 | T7: 3 | U7: 300000 | V7: NÃO
C8: =IF(AND(J4=3,K4=1),Q7,IF(AND(J4=3,K4=2),R7,IF(AND(J4=3,K4=3),P7,"-"))) -> - | N8: GoiásFomento Giro - VIP IMCF | O8: 2.16 | P8: 0 | Q8: 1.72 | R8: =Q8 -> 1.72 | S8: 36 | T8: 3 | U8: 300000
C9: =IF(AND(J4=4,K4=1),Q8,IF(AND(J4=4,K4=2),R8,IF(AND(J4=4,K4=3),P8,"-"))) -> - | N9: GoiásFomento Giro Consorciado | O9: =O8 -> 2.16 | P9: 0 | Q9: =Q8 -> 1.72 | R9: =R8 -> 1.72 | S9: 36 | T9: 3 | U9: 300000
C10: =IF(AND(J4=5,K4=1),Q9,IF(AND(J4=5,K4=2),R9,IF(AND(J4=5,K4=3),P9,"-"))) -> - | N10: GoiásFomento (GIRO)Tecnologia/PQF-IEL/Turismo/FarmaDrogas/ Contabilistas / Mulher Empreendedora | O10: 2.21 | P10: 0 | Q10: 1.77 | R10: =Q10 -> 1.77 | S10: 36 | T10: 3 | U10: 300000
C11: =IF(AND(J4=6,K4=1),Q10,IF(AND(J4=6,K4=2),R10,IF(AND(J4=6,K4=3),P10,"-"))) -> 1.77 | N11: GoiásFomento Microcrédito Produtivo | O11: 2.06 | P11: 1.65 | Q11: =P11 -> 1.65 | R11: =Q11 -> 1.65 | S11: 36 | T11: 3 | U11: 21000
C12: =IF(AND(J4=7,K4=1),Q11,IF(AND(J4=7,K4=2),R11,IF(AND(J4=7,K4=3),P11,"-"))) -> -
A14: INFORMAÇÕES
A15: VALOR FINANCIADO | B15: 60000 | C15: TAXA NOMINAL | E15: =AJ22 -> -0.0010961245 | F15: =IF(AA1=1,IF(B15<=3000,50,IF(B15<=21000,IF(B15*0.03<=420,B15*1.015*0.03,420),IF(B15<=100000,B15*0.02,2000+B15*0.005))),IF(B15*1.015<=3000,50,IF(B15*1.015<=21000,IF(B15*1.015*0.03<=420,B15*1.015*0.03,420),IF(B15<=100000,B15*1.015*0.02,2000+B15*1.015*0.005)))) -> 1218 | I15: =IF(B15<=3000,50,IF(B15<=21000,IF(B15*0.03<=420,B15*0.03,420),IF(B15<=100000,B15*0.02,2000+B15*0.005))) -> 1200 | J15: 4
A16: CARÊNCIA | B16: 6 | C16: TAXA COM BÔNUS | D16: 0.005 | F16: =IF(AB1=1,AF24,AF24*1.03) -> 931.635 | I16: =IF(B15*0.03<=420,B15*0.03,420) -> 420 | J16: 1
A17: PRAZO TOTAL | B17: 60 | C17: DATA DA PROPOSTA | D17: =TODAY() -> 46240 | F17: =IF(J16=1,IF(J21=TRUE,M24,0),IF(J21=TRUE,M24*1.001,0)) -> 0 | J17: Descontado | L17: FALSE | AL17: Receitas Totais | AM17: =SUM(AM18:AM19) -> #VALUE! | AN17: Despesas | AO17: PDD AD | AP17: Resultado | AQ17: =AQ18-AQ19 -> #VALUE! | AR17: =AQ17/D22 -> #VALUE!
A18: OPÇÕES DE GARANTIA | J18: Financiado | AL18: TAC | AM18: =F15 -> 1218 | AN18: Provisão Adicional | AO18: =D22*0.014 -> #VALUE! | AP18: Receitas | AQ18: =AM17 -> #VALUE!
A19: RENDA PARA AVAL | B19: =IF(LARGE(F23:F241,1)*3<2424,2424,LARGE(F23:F241,1)*3) -> 4385.002 | C19: ALIENAÇÃO DE IMÓVEL | D19: =IF(J21=TRUE,(B15-F19)*1.5/0.7,B15*1.5/0.7) -> 128571.43 | E19: 0.8 | F19: =IF(J21=TRUE,E19*B15,0) -> 0 | J19: FINANCIADO | L19: TRUE | AL19: JUROS | AM19: =C22 -> #VALUE! | AN19: Avaliação | AO19: 300 | AP19: Despesas | AQ19: =AO20 -> #VALUE!
A20: SIMULAÇÃO DO VALOR DAS PARCELAS | J20: Financiado | AO20: =SUM(AO18:AO19) -> #VALUE! | AW20: 16681310
A21: PARCELA | B21: AMORTIZAÇÃO | C21: JUROS | D21: VALOR AMORTIZAÇÃO | E21: SALDO DEVEDOR | F21: PARCELA COM BÔNUS | J21: FALSE | K21: TCA | L21: FAMPE | M21: =B15*E19*0.001*B17 -> 2880 | AB21: IOF - ACIMA ATÉ 365 DIAS | AJ21: TIR (PARCELA C/ BÔNUS) | AK21: TIR (PARCELA S/ BÔNUS) | AW21: 8540394.5 | AX21: =AW21*12 -> 1.0248473e+08
A22: TOTAL | C22: =SUM(C23:C242) -> #VALUE! | D22: =SUM(D23:D242) -> #VALUE! | F22: =SUM(F23:F242) -> 58299.81 | K22: ECG | L22: FGI | M22: ='Fator K - FGI'!I30 -> 3133.595 | AJ22: =IRR(AJ23:AJ107) -> -0.0010961245 | AK22: =IRR(AK23:AK107) -> #VALUE! | AW22: 86881821 | BL22: =F22-B15 -> -1700.1896
A23: 0 | C23: =D16 -> 0.005 | E23: =IF(AND(AA1=1,AB1=1,J16=1),B15,IF(AND(AA1=1,AB1=1,J16=2),B15+F17,IF(AND(AA1=1,AB1=2,J16=1),B15+F16,IF(AND(AA1=1,AB1=2,J16=3),B15+F16,IF(AND(AA1=2,AB1=1,J16=1),B15+F15,IF(AND(AA1=2,AB1=1,J16=2),B15+F15+F17,IF(AND(AA1=2,AB1=2,J16=2),B15+F17+F16+F15,IF(AND(AA1=2,AB1=2,J16=3),B15+F15+F16,IF(AND(AA1=2,AB1=2,J16=1),B15+F15+F16,IF(AND(AA1=1,AB1=2,J16=2),B15+F16+F17, IF(AND(AA1=1,AB1=1,J16=3),B15))))))))))) -> 62149.635 | K23: TCA | L23: FUNDEQ | M23: =B15*E19*0.001*B17 -> 2880 | AJ23: =-B15 -> -60000 | AK23: =AJ23 -> -60000 | AN23: 5881 | AO23: =AN23/AN24 -> 0.04216496
A24: =IF(A23<B$17,A23+1,"") -> 1 | B24: =IF(A24="","",IF(A24<=B$16,"carência","amortização")) -> carência | C24: =IF(B24="","",E23*$C$23) -> 310.74818 | D24: =IF(C24="","",IF(A24<=B$16,0,$E$23/(B$17-B$16))) -> 0 | E24: =IF(F24="","",E23-D24) -> 62149.635 | F24: =IF(D24="","",D24+C24) -> 310.74818 | I24: =B15+F15+F16+F17 -> 62149.635 | L24: 1 | M24: =IF(L24=1,M21,IF(L24=2,M22,M23)) -> 2880 | AB24: IOF | AC24: 0.0038 | AE24: =AC27*AC24 -> 228 | AF24: =IF(L19=FALSE,0,IF(AND(AH25=TRUE,B15<=30000),AE24+AE26,AE24+AE25)) -> 904.5 | AJ24: =IF(A24<=$B$17,F24,0) -> 310.74818 | AK24: =IF(A24<=$B$17,E23*$D$15+D24,0) -> 0 | AN24: 139476 | AW24: =SUM(E23:E34) -> 728531.83
A25: =IF(A24<B$17,A24+1,"") -> 2 | B25: =IF(A25="","",IF(A25<=B$16,"carência","amortização")) -> carência | C25: =IF(B25="","",E24*$C$23) -> 310.74818 | D25: =IF(C25="","",IF(A25<=B$16,0,$E$23/(B$17-B$16))) -> 0 | E25: =IF(F25="","",E24-D25) -> 62149.635 | F25: =IF(D25="","",D25+C25) -> 310.74818 | AB25: ALÍQUOTA | AC25: 4.1e-05 | AE25: =SUM(AG30:AG83) -> 676.5 | AH25: TRUE | AJ25: =IF(A25<=$B$17,F25,0) -> 310.74818 | AK25: =IF(A25<=$B$17,E24*$D$15+D25,0) -> 0
A26: =IF(A25<B$17,A25+1,"") -> 3 | B26: =IF(A26="","",IF(A26<=B$16,"carência","amortização")) -> carência | C26: =IF(B26="","",E25*$C$23) -> 310.74818 | D26: =IF(C26="","",IF(A26<=B$16,0,$E$23/(B$17-B$16))) -> 0 | E26: =IF(F26="","",E25-D26) -> 62149.635 | F26: =IF(D26="","",D26+C26) -> 310.74818 | AB26: ALÍQUOTA SIMPLES | AC26: =0.00137/100 -> 1.37e-05 | AE26: =SUM(AH30:AH308) -> 226.05 | AJ26: =IF(A26<=$B$17,F26,0) -> 310.74818 | AK26: =IF(A26<=$B$17,E25*$D$15+D26,0) -> 0 | AW26: =SUM(C24:C35) -> 3642.6592
A27: =IF(A26<B$17,A26+1,"") -> 4 | B27: =IF(A27="","",IF(A27<=B$16,"carência","amortização")) -> carência | C27: =IF(B27="","",E26*$C$23) -> 310.74818 | D27: =IF(C27="","",IF(A27<=B$16,0,$E$23/(B$17-B$16))) -> 0 | E27: =IF(F27="","",E26-D27) -> 62149.635 | F27: =IF(D27="","",D27+C27) -> 310.74818 | AB27: LIBERAÇÃO | AC27: =B15 -> 60000 | AJ27: =IF(A27<=$B$17,F27,0) -> 310.74818 | AK27: =IF(A27<=$B$17,E26*$D$15+D27,0) -> 0
A28: =IF(A27<B$17,A27+1,"") -> 5 | B28: =IF(A28="","",IF(A28<=B$16,"carência","amortização")) -> carência | C28: =IF(B28="","",E27*$C$23) -> 310.74818 | D28: =IF(C28="","",IF(A28<=B$16,0,$E$23/(B$17-B$16))) -> 0 | E28: =IF(F28="","",E27-D28) -> 62149.635 | F28: =IF(D28="","",D28+C28) -> 310.74818 | AG28: IOF NORMAL | AH28: IOF SIMPLES | AJ28: =IF(A28<=$B$17,F28,0) -> 310.74818 | AK28: =IF(A28<=$B$17,E27*$D$15+D28,0) -> 0
A29: =IF(A28<B$17,A28+1,"") -> 6 | B29: =IF(A29="","",IF(A29<=B$16,"carência","amortização")) -> carência | C29: =IF(B29="","",E28*$C$23) -> 310.74818 | D29: =IF(C29="","",IF(A29<=B$16,0,$E$23/(B$17-B$16))) -> 0 | E29: =IF(F29="","",E28-D29) -> 62149.635 | F29: =IF(D29="","",D29+C29) -> 310.74818 | AA29: 0 | AB29: =D17 -> 46240 | AC29: =IF(AB29="","",AC27) -> 60000 | AD29: =IF(AA29="","",IF(AA29<=B$16,0,B$15/(B$17-B$16))) -> 0 | AJ29: =IF(A29<=$B$17,F29,0) -> 310.74818 | AK29: =IF(A29<=$B$17,E28*$D$15+D29,0) -> 0 | AW29: =E23 -> 62149.635
A30: =IF(A29<B$17,A29+1,"") -> 7 | B30: =IF(A30="","",IF(A30<=B$16,"carência","amortização")) -> amortização | C30: =IF(B30="","",E29*$C$23) -> 310.74818 | D30: =IF(C30="","",IF(A30<=B$16,0,$E$23/(B$17-B$16))) -> 1150.9192 | E30: =IF(F30="","",E29-D30) -> 60998.716 | F30: =IF(D30="","",D30+C30) -> 1461.6673 | AA30: =IF(AA29<B$17,AA29+1,"") -> 1 | AB30: =IF(AA30="","",AB29+30) -> 46270 | AC30: =IF(AB30="","",IF(AA30<=B$16,AC29,AC29-AD30)) -> 60000 | AD30: =IF(AA30="","",IF(AA30<=B$16,0,B$15/(B$17-B$16))) -> 0 | AE30: =IF(AD30="","",AB30-AB29) -> 30 | AF30: =IF(AE30="","",AB30-AB$29) -> 30 | AG30: =IF(AF30="","",IF(AF30<365,AF30*AC$25*AD30,365*AD30*AC$25)) -> 0 | AH30: =IF(AF30="","",IF(AF30<365,AF30*AC$26*AD30,365*AD30*AC$26)) -> 0 | AJ30: =IF(A30<=$B$17,F30,0) -> 1461.6673 | AK30: =IF(A30<=$B$17,E29*$D$15+D30,0) -> 1150.9192 | AW30: =AW29*0.016 -> 994.39416
A31: =IF(A30<B$17,A30+1,"") -> 8 | B31: =IF(A31="","",IF(A31<=B$16,"carência","amortização")) -> amortização | C31: =IF(B31="","",E30*$C$23) -> 304.99358 | D31: =IF(C31="","",IF(A31<=B$16,0,$E$23/(B$17-B$16))) -> 1150.9192 | E31: =IF(F31="","",E30-D31) -> 59847.797 | F31: =IF(D31="","",D31+C31) -> 1455.9127 | AA31: =IF(AA30<B$17,AA30+1,"") -> 2 | AB31: =IF(AA31="","",AB30+30) -> 46300 | AC31: =IF(AB31="","",IF(AA31<=B$16,AC30,AC30-AD31)) -> 60000 | AD31: =IF(AA31="","",IF(AA31<=B$16,0,B$15/(B$17-B$16))) -> 0 | AE31: =IF(AD31="","",AB31-AB30) -> 30 | AF31: =IF(AE31="","",AB31-AB$29) -> 60 | AG31: =IF(AF31="","",IF(AF31<365,AF31*AC$25*AD31,365*AD31*AC$25)) -> 0 | AH31: =IF(AF31="","",IF(AF31<365,AF31*AC$26*AD31,365*AD31*AC$26)) -> 0 | AJ31: =IF(A31<=$B$17,F31,0) -> 1455.9127 | AK31: =IF(A31<=$B$17,E30*$D$15+D31,0) -> 1150.9192
A32: =IF(A31<B$17,A31+1,"") -> 9 | B32: =IF(A32="","",IF(A32<=B$16,"carência","amortização")) -> amortização | C32: =IF(B32="","",E31*$C$23) -> 299.23898 | D32: =IF(C32="","",IF(A32<=B$16,0,$E$23/(B$17-B$16))) -> 1150.9192 | E32: =IF(F32="","",E31-D32) -> 58696.878 | F32: =IF(D32="","",D32+C32) -> 1450.1582 | AA32: =IF(AA31<B$17,AA31+1,"") -> 3 | AB32: =IF(AA32="","",AB31+30) -> 46330 | AC32: =IF(AB32="","",IF(AA32<=B$16,AC31,AC31-AD32)) -> 60000 | AD32: =IF(AA32="","",IF(AA32<=B$16,0,B$15/(B$17-B$16))) -> 0 | AE32: =IF(AD32="","",AB32-AB31) -> 30 | AF32: =IF(AE32="","",AB32-AB$29) -> 90 | AG32: =IF(AF32="","",IF(AF32<365,AF32*AC$25*AD32,365*AD32*AC$25)) -> 0 | AH32: =IF(AF32="","",IF(AF32<365,AF32*AC$26*AD32,365*AD32*AC$26)) -> 0 | AJ32: =IF(A32<=$B$17,F32,0) -> 1450.1582 | AK32: =IF(A32<=$B$17,E31*$D$15+D32,0) -> 1150.9192 | AW32: GFG VIP | AX32: Fungetur Giro
A33: =IF(A32<B$17,A32+1,"") -> 10 | B33: =IF(A33="","",IF(A33<=B$16,"carência","amortização")) -> amortização | C33: =IF(B33="","",E32*$C$23) -> 293.48439 | D33: =IF(C33="","",IF(A33<=B$16,0,$E$23/(B$17-B$16))) -> 1150.9192 | E33: =IF(F33="","",E32-D33) -> 57545.958 | F33: =IF(D33="","",D33+C33) -> 1444.4036 | AA33: =IF(AA32<B$17,AA32+1,"") -> 4 | AB33: =IF(AA33="","",AB32+30) -> 46360 | AC33: =IF(AB33="","",IF(AA33<=B$16,AC32,AC32-AD33)) -> 60000 | AD33: =IF(AA33="","",IF(AA33<=B$16,0,B$15/(B$17-B$16))) -> 0 | AE33: =IF(AD33="","",AB33-AB32) -> 30 | AF33: =IF(AE33="","",AB33-AB$29) -> 120 | AG33: =IF(AF33="","",IF(AF33<365,AF33*AC$25*AD33,365*AD33*AC$25)) -> 0 | AH33: =IF(AF33="","",IF(AF33<365,AF33*AC$26*AD33,365*AD33*AC$26)) -> 0 | AJ33: =IF(A33<=$B$17,F33,0) -> 1444.4036 | AK33: =IF(A33<=$B$17,E32*$D$15+D33,0) -> 1150.9192 | AV33: Valor Financiado | AW33: 100000 | AX33: 100000
A34: =IF(A33<B$17,A33+1,"") -> 11 | B34: =IF(A34="","",IF(A34<=B$16,"carência","amortização")) -> amortização | C34: =IF(B34="","",E33*$C$23) -> 287.72979 | D34: =IF(C34="","",IF(A34<=B$16,0,$E$23/(B$17-B$16))) -> 1150.9192 | E34: =IF(F34="","",E33-D34) -> 56395.039 | F34: =IF(D34="","",D34+C34) -> 1438.649 | AA34: =IF(AA33<B$17,AA33+1,"") -> 5 | AB34: =IF(AA34="","",AB33+30) -> 46390 | AC34: =IF(AB34="","",IF(AA34<=B$16,AC33,AC33-AD34)) -> 60000 | AD34: =IF(AA34="","",IF(AA34<=B$16,0,B$15/(B$17-B$16))) -> 0 | AE34: =IF(AD34="","",AB34-AB33) -> 30 | AF34: =IF(AE34="","",AB34-AB$29) -> 150 | AG34: =IF(AF34="","",IF(AF34<365,AF34*AC$25*AD34,365*AD34*AC$25)) -> 0 | AH34: =IF(AF34="","",IF(AF34<365,AF34*AC$26*AD34,365*AD34*AC$26)) -> 0 | AJ34: =IF(A34<=$B$17,F34,0) -> 1438.649 | AK34: =IF(A34<=$B$17,E33*$D$15+D34,0) -> 1150.9192 | AV34: Prazo | AW34: 36 | AX34: 48
A35: =IF(A34<B$17,A34+1,"") -> 12 | B35: =IF(A35="","",IF(A35<=B$16,"carência","amortização")) -> amortização | C35: =IF(B35="","",E34*$C$23) -> 281.9752 | D35: =IF(C35="","",IF(A35<=B$16,0,$E$23/(B$17-B$16))) -> 1150.9192 | E35: =IF(F35="","",E34-D35) -> 55244.12 | F35: =IF(D35="","",D35+C35) -> 1432.8944 | AA35: =IF(AA34<B$17,AA34+1,"") -> 6 | AB35: =IF(AA35="","",AB34+30) -> 46420 | AC35: =IF(AB35="","",IF(AA35<=B$16,AC34,AC34-AD35)) -> 60000 | AD35: =IF(AA35="","",IF(AA35<=B$16,0,B$15/(B$17-B$16))) -> 0 | AE35: =IF(AD35="","",AB35-AB34) -> 30 | AF35: =IF(AE35="","",AB35-AB$29) -> 180 | AG35: =IF(AF35="","",IF(AF35<365,AF35*AC$25*AD35,365*AD35*AC$25)) -> 0 | AH35: =IF(AF35="","",IF(AF35<365,AF35*AC$26*AD35,365*AD35*AC$26)) -> 0 | AJ35: =IF(A35<=$B$17,F35,0) -> 1432.8944 | AK35: =IF(A35<=$B$17,E34*$D$15+D35,0) -> 1150.9192 | AV35: Carência | AW35: 6 | AX35: 6
A36: =IF(A35<B$17,A35+1,"") -> 13 | B36: =IF(A36="","",IF(A36<=B$16,"carência","amortização")) -> amortização | C36: =IF(B36="","",E35*$C$23) -> 276.2206 | D36: =IF(C36="","",IF(A36<=B$16,0,$E$23/(B$17-B$16))) -> 1150.9192 | E36: =IF(F36="","",E35-D36) -> 54093.201 | F36: =IF(D36="","",D36+C36) -> 1427.1398 | AA36: =IF(AA35<B$17,AA35+1,"") -> 7 | AB36: =IF(AA36="","",AB35+30) -> 46450 | AC36: =IF(AB36="","",IF(AA36<=B$16,AC35,AC35-AD36)) -> 58888.889 | AD36: =IF(AA36="","",IF(AA36<=B$16,0,B$15/(B$17-B$16))) -> 1111.1111 | AE36: =IF(AD36="","",AB36-AB35) -> 30 | AF36: =IF(AE36="","",AB36-AB$29) -> 210 | AG36: =IF(AF36="","",IF(AF36<365,AF36*AC$25*AD36,365*AD36*AC$25)) -> 9.5666667 | AH36: =IF(AF36="","",IF(AF36<365,AF36*AC$26*AD36,365*AD36*AC$26)) -> 3.1966667 | AJ36: =IF(A36<=$B$17,F36,0) -> 1427.1398 | AK36: =IF(A36<=$B$17,E35*$D$15+D36,0) -> 1150.9192 | AV36: Juros | AW36: 0.0155 | AX36: =(1.05)^(1/12)-1 -> 0.0040741238
A37: =IF(A36<B$17,A36+1,"") -> 14 | B37: =IF(A37="","",IF(A37<=B$16,"carência","amortização")) -> amortização | C37: =IF(B37="","",E36*$C$23) -> 270.466 | D37: =IF(C37="","",IF(A37<=B$16,0,$E$23/(B$17-B$16))) -> 1150.9192 | E37: =IF(F37="","",E36-D37) -> 52942.282 | F37: =IF(D37="","",D37+C37) -> 1421.3852 | AA37: =IF(AA36<B$17,AA36+1,"") -> 8 | AB37: =IF(AA37="","",AB36+30) -> 46480 | AC37: =IF(AB37="","",IF(AA37<=B$16,AC36,AC36-AD37)) -> 57777.778 | AD37: =IF(AA37="","",IF(AA37<=B$16,0,B$15/(B$17-B$16))) -> 1111.1111 | AE37: =IF(AD37="","",AB37-AB36) -> 30 | AF37: =IF(AE37="","",AB37-AB$29) -> 240 | AG37: =IF(AF37="","",IF(AF37<365,AF37*AC$25*AD37,365*AD37*AC$25)) -> 10.933333 | AH37: =IF(AF37="","",IF(AF37<365,AF37*AC$26*AD37,365*AD37*AC$26)) -> 3.6533333 | AJ37: =IF(A37<=$B$17,F37,0) -> 1421.3852 | AK37: =IF(A37<=$B$17,E36*$D$15+D37,0) -> 1150.9192 | AV37: Receita Juros | AW37: 18519.324 | AX37: 5090.838 | AY37: =AW37/AX37-1 -> 2.6377752
A38: =IF(A37<B$17,A37+1,"") -> 15 | B38: =IF(A38="","",IF(A38<=B$16,"carência","amortização")) -> amortização | C38: =IF(B38="","",E37*$C$23) -> 264.71141 | D38: =IF(C38="","",IF(A38<=B$16,0,$E$23/(B$17-B$16))) -> 1150.9192 | E38: =IF(F38="","",E37-D38) -> 51791.363 | F38: =IF(D38="","",D38+C38) -> 1415.6306 | AA38: =IF(AA37<B$17,AA37+1,"") -> 9 | AB38: =IF(AA38="","",AB37+30) -> 46510 | AC38: =IF(AB38="","",IF(AA38<=B$16,AC37,AC37-AD38)) -> 56666.667 | AD38: =IF(AA38="","",IF(AA38<=B$16,0,B$15/(B$17-B$16))) -> 1111.1111 | AE38: =IF(AD38="","",AB38-AB37) -> 30 | AF38: =IF(AE38="","",AB38-AB$29) -> 270 | AG38: =IF(AF38="","",IF(AF38<365,AF38*AC$25*AD38,365*AD38*AC$25)) -> 12.3 | AH38: =IF(AF38="","",IF(AF38<365,AF38*AC$26*AD38,365*AD38*AC$26)) -> 4.11 | AJ38: =IF(A38<=$B$17,F38,0) -> 1415.6306 | AK38: =IF(A38<=$B$17,E37*$D$15+D38,0) -> 1150.9192 | AV38: Rentabilidade (12 meses) | AW38: =AW37/AW33 -> 0.18519324 | AX38: =AX37/AX33 -> 0.05090838 | AY38: =AW38/AX38-1 -> 2.6377752
A39: =IF(A38<B$17,A38+1,"") -> 16 | B39: =IF(A39="","",IF(A39<=B$16,"carência","amortização")) -> amortização | C39: =IF(B39="","",E38*$C$23) -> 258.95681 | D39: =IF(C39="","",IF(A39<=B$16,0,$E$23/(B$17-B$16))) -> 1150.9192 | E39: =IF(F39="","",E38-D39) -> 50640.443 | F39: =IF(D39="","",D39+C39) -> 1409.876 | AA39: =IF(AA38<B$17,AA38+1,"") -> 10 | AB39: =IF(AA39="","",AB38+30) -> 46540 | AC39: =IF(AB39="","",IF(AA39<=B$16,AC38,AC38-AD39)) -> 55555.556 | AD39: =IF(AA39="","",IF(AA39<=B$16,0,B$15/(B$17-B$16))) -> 1111.1111 | AE39: =IF(AD39="","",AB39-AB38) -> 30 | AF39: =IF(AE39="","",AB39-AB$29) -> 300 | AG39: =IF(AF39="","",IF(AF39<365,AF39*AC$25*AD39,365*AD39*AC$25)) -> 13.666667 | AH39: =IF(AF39="","",IF(AF39<365,AF39*AC$26*AD39,365*AD39*AC$26)) -> 4.5666667 | AJ39: =IF(A39<=$B$17,F39,0) -> 1409.876 | AK39: =IF(A39<=$B$17,E38*$D$15+D39,0) -> 1150.9192
A40: =IF(A39<B$17,A39+1,"") -> 17 | B40: =IF(A40="","",IF(A40<=B$16,"carência","amortização")) -> amortização | C40: =IF(B40="","",E39*$C$23) -> 253.20222 | D40: =IF(C40="","",IF(A40<=B$16,0,$E$23/(B$17-B$16))) -> 1150.9192 | E40: =IF(F40="","",E39-D40) -> 49489.524 | F40: =IF(D40="","",D40+C40) -> 1404.1214 | AA40: =IF(AA39<B$17,AA39+1,"") -> 11 | AB40: =IF(AA40="","",AB39+30) -> 46570 | AC40: =IF(AB40="","",IF(AA40<=B$16,AC39,AC39-AD40)) -> 54444.444 | AD40: =IF(AA40="","",IF(AA40<=B$16,0,B$15/(B$17-B$16))) -> 1111.1111 | AE40: =IF(AD40="","",AB40-AB39) -> 30 | AF40: =IF(AE40="","",AB40-AB$29) -> 330 | AG40: =IF(AF40="","",IF(AF40<365,AF40*AC$25*AD40,365*AD40*AC$25)) -> 15.033333 | AH40: =IF(AF40="","",IF(AF40<365,AF40*AC$26*AD40,365*AD40*AC$26)) -> 5.0233333 | AJ40: =IF(A40<=$B$17,F40,0) -> 1404.1214 | AK40: =IF(A40<=$B$17,E39*$D$15+D40,0) -> 1150.9192
A41: =IF(A40<B$17,A40+1,"") -> 18 | B41: =IF(A41="","",IF(A41<=B$16,"carência","amortização")) -> amortização | C41: =IF(B41="","",E40*$C$23) -> 247.44762 | D41: =IF(C41="","",IF(A41<=B$16,0,$E$23/(B$17-B$16))) -> 1150.9192 | E41: =IF(F41="","",E40-D41) -> 48338.605 | F41: =IF(D41="","",D41+C41) -> 1398.3668 | AA41: =IF(AA40<B$17,AA40+1,"") -> 12 | AB41: =IF(AA41="","",AB40+30) -> 46600 | AC41: =IF(AB41="","",IF(AA41<=B$16,AC40,AC40-AD41)) -> 53333.333 | AD41: =IF(AA41="","",IF(AA41<=B$16,0,B$15/(B$17-B$16))) -> 1111.1111 | AE41: =IF(AD41="","",AB41-AB40) -> 30 | AF41: =IF(AE41="","",AB41-AB$29) -> 360 | AG41: =IF(AF41="","",IF(AF41<365,AF41*AC$25*AD41,365*AD41*AC$25)) -> 16.4 | AH41: =IF(AF41="","",IF(AF41<365,AF41*AC$26*AD41,365*AD41*AC$26)) -> 5.48 | AJ41: =IF(A41<=$B$17,F41,0) -> 1398.3668 | AK41: =IF(A41<=$B$17,E40*$D$15+D41,0) -> 1150.9192
...

Sheet Fator K - FGI
B4: Contrato: | C4: 46055-000-4 | F4: Prazo | G4: ='Linhas Giro Puro'!B17 -> 60
B5: Ninja Moto Peças Ltda | F5: Valor Financiado | G5: ='Linhas Giro Puro'!B15 -> 60000
B8: IOF | C8: 945.25 | F8: Prazo Total da Operação | G8: Valor Fator K
B9: TAC | C9: 1039.92 | F9: 3 | G9: 0.0142
B10: FGI | C10: 2347.16 | F10: 4 | G10: 0.0062
B11: Total | C11: =SUM(C8:C10) -> 4332.33 | F11: 5 | G11: 0.0062
B12: Líquido | C12: 50000 | F12: 6 | G12: 0.0062
B13: Financiado | C13: =C12+C11 -> 54332.33 | F13: 7 | G13: 0.0042
F14: 8 | G14: 0.0042
F15: 9 | G15: 0.0042
F16: 10 | G16: 0.0031
F17: 11 | G17: 0.0031
F18: 12 | G18: 0.0031
F19: 13 | G19: 0.0027
F20: 14 | G20: 0.0027
F21: 15 | G21: 0.0027
F22: 16 | G22: 0.0024
F23: 17 | G23: 0.0024
F24: 18 | G24: 0.0024
F25: 19 | G25: 0.0022 | H25: K = | I25: =_xlfn.XLOOKUP(I28,F9:F110,G9:G110) -> 0.001
F26: 20 | G26: 0.0022 | H26: VL | I26: =G5+'Linhas Giro Puro'!F15+'Linhas Giro Puro'!F16 -> 62149.635
F27: 21 | G27: 0.0022 | H27: %G | I27: 0.8
F28: 22 | G28: 0.002 | H28: P | I28: =G4 -> 60
F29: 23 | G29: 0.002
F30: 24 | G30: 0.002 | H30: ECG = | I30: =(I25*(I26*I27)*I28)/(1-(I25*I27*I28)) -> 3133.595
F31: 25 | G31: 0.0018
F32: 26 | G32: 0.0018
F33: 27 | G33: 0.0018
F34: 28 | G34: 0.0017
F35: 29 | G35: 0.0017
F36: 30 | G36: 0.0017
F37: 31 | G37: 0.0016
F38: 32 | G38: 0.0016
F39: 33 | G39: 0.0016
F40: 34 | G40: 0.0015
F41: 35 | G41: 0.0015
F42: 36 | G42: 0.0015
... F110: 103 | G110: 0.0005

Sheet Mais Crédito
A1: AGÊNCIA DE FOMENTO DE GOIÁS S/A | AA1: 1 | AB1: 1
A2: IMPORTANTE: Os valores simulados podem variar e estão sujeitos à data de vencimento da parcela e da liberação do crédito; O financiamento e condições são sujeitas à aprovação final da análise de crédito; Valores calculados com base na taxa líquida para quando não há atraso nos pagamentos.
A3: LINHA DE CAPITAL DE GIRO/INVESTIMENTO | AA3: TAC | AB3: IOF
A4: LINHA | J4: 1 | K4: 1 | N4: LINHA | O4: TAXA (a.m.) | P4: TAXA BONUS | Q4: CG1 (a.m.) | R4: CG2 (a.m.) | S4: PRAZO (meses) | T4: CARÊNCIA (até meses) | U4: LIMITE | V4: GARANTIA | AA4: Descontado | AB4: Descontado
N5: Mais Crédito Aval do FUNDEQ | O5: 1.69 | P5: 0 | Q5: 1.69 | R5: =Q5 -> 1.69 | S5: 24 | T5: 3 | U5: 21000 | V5: CG1 | AA5: Financiado | AB5: Financiado
C6: =IF(AND(J4=1,K4=1),Q5,IF(AND(J4=1,K4=2),R5,IF(AND(J4=1,K4=3),P5,"-"))) -> 1.69 | N6: Mais CrédIto com parceria - Juro Zero e Aval | O6: 1.69 | P6: 0 | Q6: 0 | R6: 0 | S6: 24 | T6: 3 | U6: 21000 | V6: CG2
C7: =IF(AND(J4=2,K4=1),Q6,IF(AND(J4=2,K4=2),R6,IF(AND(J4=2,K4=3),P6,"-"))) -> - | N7: Mais Crédito Equalização de Juros FUNDEQ | O7: 1.69 | P7: 0 | Q7: 0 | R7: 0 | S7: 24 | T7: 3 | U7: 21000 | V7: NÃO
C8: =IF(AND(J4=3,K4=1),Q7,IF(AND(J4=3,K4=2),R7,IF(AND(J4=3,K4=3),P7,"-"))) -> - | N8: GoiásFomento Giro - VIP IMCF | O8: 1.9 | P8: 0 | Q8: 1.47 | R8: =Q8 -> 1.47 | S8: 36 | T8: 3 | U8: 300000
C9: =IF(AND(J4=4,K4=1),Q8,IF(AND(J4=4,K4=2),R8,IF(AND(J4=4,K4=3),P8,"-"))) -> - | N9: GoiásFomento Giro Consorciado | O9: 1.9 | P9: 0 | Q9: 1.47 | R9: =Q9 -> 1.47 | S9: 36 | T9: 3 | U9: 300000
C10: =IF(AND(J4=5,K4=1),Q9,IF(AND(J4=5,K4=2),R9,IF(AND(J4=5,K4=3),P9,"-"))) -> - | N10: GoiásFomento (GIRO)Tecnologia/PQF-IEL/Turismo/FarmaDrogas/ Contabilistas | O10: 2.05 | P10: 0 | Q10: 1.58 | R10: =Q10 -> 1.58 | S10: 36 | T10: 3 | U10: 300000
C11: =IF(AND(J4=6,K4=1),Q10,IF(AND(J4=6,K4=2),R10,IF(AND(J4=6,K4=3),P10,"-"))) -> - | N11: GoiásFomento Microcrédito Produtivo | O11: 1.82 | P11: 1.5 | Q11: 1.5 | R11: =Q11 -> 1.5 | S11: 36 | T11: 3 | U11: 21000
C12: =IF(AND(J4=7,K4=1),Q11,IF(AND(J4=7,K4=2),R11,IF(AND(J4=7,K4=3),P11,"-"))) -> -
K13: ASSAT1
A14: INFORMAÇÕES | I14: =IF(B15<=5000,IF(AND(B15<=5000,J21=TRUE),D15,0),0.0169) -> 0.0169
A15: VALOR FINANCIADO | B15: 5000 | C15: TAXA NOMINAL | D15: =IF(J4=1,O5,IF(J4=2,O6,IF(J4=3,O7,IF(J4=4,O8,IF(J4=5,O9,IF(J4=6,O10,IF(J4=7,O11)))))))/100 -> 0.0169 | F15: =IF(B15<=3000,50,IF(B15<=21000,IF(B15*0.03<=420,B15*0.03,420),IF(B15<=100000,B15*0.02,2000+B15*0.005))) -> 150 | I15: =IF(B15<=3000,50,IF(B15<=21000,IF(B15*0.03<=420,B15*0.03,420),IF(B15<=100000,B15*0.02,2000+B15*0.005))) -> 150 | J15: 4
A16: CARÊNCIA | B16: 6 | C16: TAXA COM BÔNUS | D16: =IF(B15<=5000,IF(AND(B15<=5000,J21=TRUE),D15,0),0.0169) -> 0.0169 | F16: =AF24 -> 42.9065 | I16: =IF(B15*0.03<=420,B15*0.03,420) -> 150 | J16: 1 | AP16: 36
A17: PRAZO TOTAL | B17: 36 | C17: DATA DA PROPOSTA | D17: =TODAY() -> 46240 | F17: =IF(B15>5000,IF(B15>5000,IF(K4=1,(B15*E19*0.001*B17),IF(K4=2,(F19*0.001*B17),IF(K4=3,0,""))),0),IF(J21=TRUE,IF(K4=1,(B15*E19*0.001*B17),IF(K4=2,(F19*0.001*B17),IF(K4=3,0,""))),0)) -> 180 | J17: Descontado | L17: FALSE
A18: OPÇÕES DE GARANTIA | J18: Financiado
A19: RENDA PARA AVAL | B19: =IF(LARGE(F23:F241,1)*3<2424,2424,LARGE(F23:F241,1)*3) -> 2424 | C19: ALIENAÇÃO DE IMÓVEL | D19: =IF(J21=TRUE,(B15-F19)*1.5/0.7,B15*1.5/0.7) -> 0 | E19: 1 | F19: =IF(F17<>0,IF(K4=1,(B15*E19),IF(K4=2,B15*E19,IF(K4=3,0,""))),0) -> 5000 | J19: FINANCIADO | L19: TRUE
A20: SIMULAÇÃO DO VALOR DAS PARCELAS | J20: Financiado | AM20: =IRR(AM23:AM47) -> -0.0059870182
A21: PARCELA | B21: AMORTIZAÇÃO | C21: JUROS | D21: VALOR AMORTIZAÇÃO | E21: SALDO DEVEDOR | F21: PARCELA COM BÔNUS | J21: TRUE | AB21: IOF - ACIMA ATÉ 365 DIAS
A22: TOTAL | C22: =SUM(C23:C242) -> 1816.7669 | D22: =SUM(D23:D242) -> 5000 | F22: =SUM(F23:F242) -> 6816.75
A23: 0 | C23: =D16 -> 0.0169 | E23: =IF(AND(AA1=1,AB1=1,J16=1),B15,IF(AND(AA1=1,AB1=1,J16=2),B15+F17,IF(AND(AA1=1,AB1=2,J16=1),B15+F16,IF(AND(AA1=1,AB1=2,J16=3),B15+F16,IF(AND(AA1=2,AB1=1,J16=1),B15+F15,IF(AND(AA1=2,AB1=1,J16=2),B15+F15+F17,IF(AND(AA1=2,AB1=2,J16=2),B15+F17+F16+F15,IF(AND(AA1=2,AB1=2,J16=3),B15+F15+F16,IF(AND(AA1=2,AB1=2,J16=1),B15+F15+F16,IF(AND(AA1=1,AB1=2,J16=2),B15+F16+F17, IF(AND(AA1=1,AB1=1,J16=3),B15))))))))))) -> 5000 | AM23: =-B15 -> -5000
A24: =IF(A23<B$17,A23+1,"") -> 1 | B24: =IF(A24="","",IF(A24<=B$16,"carência","amortização")) -> carência | C24: =IF(B24="","",E23*$C$23) -> 84.5 | D24: =IF(C24="","",IF(A24<=B$16,0,B$15/(B$17-B$16))) -> 0 | E24: =IF(F24="","",E23-D24) -> 5000 | F24: =IF(D24="","",D24+C24) -> 84.5 | AB24: IOF | AC24: 0.0038 | AE24: =AC27*AC24 -> 19 | AF24: =IF(L19=FALSE,0,IF(AND(AH25=TRUE,B15<=30000),AE24+AE26,AE24+AE25)) -> 42.9065 | AM24: =F24 -> 84.5
A25: =IF(A24<B$17,A24+1,"") -> 2 | B25: =IF(A25="","",IF(A25<=B$16,"carência","amortização")) -> carência | C25: =IF(B25="","",E24*$C$23) -> 84.5 | D25: =IF(C25="","",IF(A25<=B$16,0,B$15/(B$17-B$16))) -> 0 | E25: =IF(F25="","",E24-D25) -> 5000 | F25: =IF(D25="","",D25+C25) -> 84.5 | AB25: ALÍQUOTA | AC25: 4.1e-05 | AE25: =SUM(AG30:AG83) -> 71.545 | AH25: TRUE | AM25: =F25 -> 84.5
A26: =IF(A25<B$17,A25+1,"") -> 3 | B26: =IF(A26="","",IF(A26<=B$16,"carência","amortização")) -> carência | C26: =IF(B26="","",E25*$C$23) -> 84.5 | D26: =IF(C26="","",IF(A26<=B$16,0,B$15/(B$17-B$16))) -> 0 | E26: =IF(F26="","",E25-D26) -> 5000 | F26: =IF(D26="","",D26+C26) -> 84.5 | AB26: ALÍQUOTA SIMPLES | AC26: =0.00137/100 -> 1.37e-05 | AE26: =SUM(AH30:AH308) -> 23.9065 | AM26: =F26 -> 84.5
A27: =IF(A26<B$17,A26+1,"") -> 4 | B27: =IF(A27="","",IF(A27<=B$16,"carência","amortização")) -> carência | C27: =IF(B27="","",E26*$C$23) -> 84.5 | D27: =IF(C27="","",IF(A27<=B$16,0,B$15/(B$17-B$16))) -> 0 | E27: =IF(F27="","",E26-D27) -> 5000 | F27: =IF(D27="","",D27+C27) -> 84.5 | AB27: LIBERAÇÃO | AC27: =B15 -> 5000 | AM27: =F27 -> 84.5 | AP27: =F27/0.3 -> 281.66667 | AQ27: =AP27/0.2 -> 1408.3333 | AS27: =F27/0.2 -> 422.5 | AU27: 81000
A28: =IF(A27<B$17,A27+1,"") -> 5 | B28: =IF(A28="","",IF(A28<=B$16,"carência","amortização")) -> carência | C28: =IF(B28="","",E27*$C$23) -> 84.5 | D28: =IF(C28="","",IF(A28<=B$16,0,B$15/(B$17-B$16))) -> 0 | E28: =IF(F28="","",E27-D28) -> 5000 | F28: =IF(D28="","",D28+C28) -> 84.5 | AG28: IOF NORMAL | AH28: IOF SIMPLES | AM28: =F28 -> 84.5 | AU28: =AU27/12 -> 6750
A29: =IF(A28<B$17,A28+1,"") -> 6 | B29: =IF(A29="","",IF(A29<=B$16,"carência","amortização")) -> carência | C29: =IF(B29="","",E28*$C$23) -> 84.5 | D29: =IF(C29="","",IF(A29<=B$16,0,B$15/(B$17-B$16))) -> 0 | E29: =IF(F29="","",E28-D29) -> 5000 | F29: =IF(D29="","",D29+C29) -> 84.5 | AA29: 0 | AB29: =D17 -> 46240 | AC29: =IF(AB29="","",AC27) -> 5000 | AD29: =IF(AA29="","",IF(AA29<=B$16,0,B$15/(B$17-B$16))) -> 0 | AM29: =F29 -> 84.5 | AU29: =F27/AU28 -> 0.012518519
A30: =IF(A29<B$17,A29+1,"") -> 7 | B30: =IF(A30="","",IF(A30<=B$16,"carência","amortização")) -> amortização | C30: =IF(B30="","",E29*$C$23) -> 84.5 | D30: =IF(C30="","",IF(A30<=B$16,0,B$15/(B$17-B$16))) -> 166.66667 | E30: =IF(F30="","",E29-D30) -> 4833.3333 | F30: =IF(D30="","",D30+C30) -> 251.16667 | AA30: =IF(AA29<B$17,AA29+1,"") -> 1 | AB30: =IF(AA30="","",AB29+30) -> 46270 | AC30: =IF(AB30="","",IF(AA30<=B$16,AC29,AC29-AD30)) -> 5000 | AD30: =IF(AA30="","",IF(AA30<=B$16,0,B$15/(B$17-B$16))) -> 0 | AE30: =IF(AD30="","",AB30-AB29) -> 30 | AF30: =IF(AE30="","",AB30-AB$29) -> 30 | AG30: =IF(AF30="","",IF(AF30<365,AF30*AC$25*AD30,365*AD30*AC$25)) -> 0 | AH30: =IF(AF30="","",IF(AF30<365,AF30*AC$26*AD30,365*AD30*AC$26)) -> 0 | AM30: =F30 -> 251.16667 | AN30: =F30*12 -> 3014
A31: =IF(A30<B$17,A30+1,"") -> 8 | B31: =IF(A31="","",IF(A31<=B$16,"carência","amortização")) -> amortização | C31: =IF(B31="","",E30*$C$23) -> 81.683333 | D31: =IF(C31="","",IF(A31<=B$16,0,B$15/(B$17-B$16))) -> 166.66667 | E31: =IF(F31="","",E30-D31) -> 4666.6667 | F31: =IF(D31="","",D31+C31) -> 248.35 | AA31: =IF(AA30<B$17,AA30+1,"") -> 2 | AB31: =IF(AA31="","",AB30+30) -> 46300 | AC31: =IF(AB31="","",IF(AA31<=B$16,AC30,AC30-AD31)) -> 5000 | AD31: =IF(AA31="","",IF(AA31<=B$16,0,B$15/(B$17-B$16))) -> 0 | AE31: =IF(AD31="","",AB31-AB30) -> 30 | AF31: =IF(AE31="","",AB31-AB$29) -> 60 | AG31: =IF(AF31="","",IF(AF31<365,AF31*AC$25*AD31,365*AD31*AC$25)) -> 0 | AH31: =IF(AF31="","",IF(AF31<365,AF31*AC$26*AD31,365*AD31*AC$26)) -> 0 | AM31: =F31 -> 248.35 | AU31: =AU28*0.1 -> 675
A32: =IF(A31<B$17,A31+1,"") -> 9 | B32: =IF(A32="","",IF(A32<=B$16,"carência","amortização")) -> amortização | C32: =IF(B32="","",E31*$C$23) -> 78.866667 | D32: =IF(C32="","",IF(A32<=B$16,0,B$15/(B$17-B$16))) -> 166.66667 | E32: =IF(F32="","",E31-D32) -> 4500 | F32: =IF(D32="","",D32+C32) -> 245.53333 | AA32: =IF(AA31<B$17,AA31+1,"") -> 3 | AB32: =IF(AA32="","",AB31+30) -> 46330 | AC32: =IF(AB32="","",IF(AA32<=B$16,AC31,AC31-AD32)) -> 5000 | AD32: =IF(AA32="","",IF(AA32<=B$16,0,B$15/(B$17-B$16))) -> 0 | AE32: =IF(AD32="","",AB32-AB31) -> 30 | AF32: =IF(AE32="","",AB32-AB$29) -> 90 | AG32: =IF(AF32="","",IF(AF32<365,AF32*AC$25*AD32,365*AD32*AC$25)) -> 0 | AH32: =IF(AF32="","",IF(AF32<365,AF32*AC$26*AD32,365*AD32*AC$26)) -> 0 | AM32: =F32 -> 245.53333
A33: =IF(A32<B$17,A32+1,"") -> 10 | B33: =IF(A33="","",IF(A33<=B$16,"carência","amortização")) -> amortização | C33: =IF(B33="","",E32*$C$23) -> 76.05 | D33: =IF(C33="","",IF(A33<=B$16,0,B$15/(B$17-B$16))) -> 166.66667 | E33: =IF(F33="","",E32-D33) -> 4333.3333 | F33: =IF(D33="","",D33+C33) -> 242.71667 | AA33: =IF(AA32<B$17,AA32+1,"") -> 4 | AB33: =IF(AA33="","",AB32+30) -> 46360 | AC33: =IF(AB33="","",IF(AA33<=B$16,AC32,AC32-AD33)) -> 5000 | AD33: =IF(AA33="","",IF(AA33<=B$16,0,B$15/(B$17-B$16))) -> 0 | AE33: =IF(AD33="","",AB33-AB32) -> 30 | AF33: =IF(AE33="","",AB33-AB$29) -> 120 | AG33: =IF(AF33="","",IF(AF33<365,AF33*AC$25*AD33,365*AD33*AC$25)) -> 0 | AH33: =IF(AF33="","",IF(AF33<365,AF33*AC$26*AD33,365*AD33*AC$26)) -> 0 | AM33: =F33 -> 242.71667
A34: =IF(A33<B$17,A33+1,"") -> 11 | B34: =IF(A34="","",IF(A34<=B$16,"carência","amortização")) -> amortização | C34: =IF(B34="","",E33*$C$23) -> 73.233333 | D34: =IF(C34="","",IF(A34<=B$16,0,B$15/(B$17-B$16))) -> 166.66667 | E34: =IF(F34="","",E33-D34) -> 4166.6667 | F34: =IF(D34="","",D34+C34) -> 239.9 | AA34: =IF(AA33<B$17,AA33+1,"") -> 5 | AB34: =IF(AA34="","",AB33+30) -> 46390 | AC34: =IF(AB34="","",IF(AA34<=B$16,AC33,AC33-AD34)) -> 5000 | AD34: =IF(AA34="","",IF(AA34<=B$16,0,B$15/(B$17-B$16))) -> 0 | AE34: =IF(AD34="","",AB34-AB33) -> 30 | AF34: =IF(AE34="","",AB34-AB$29) -> 150 | AG34: =IF(AF34="","",IF(AF34<365,AF34*AC$25*AD34,365*AD34*AC$25)) -> 0 | AH34: =IF(AF34="","",IF(AF34<365,AF34*AC$26*AD34,365*AD34*AC$26)) -> 0 | AM34: =F34 -> 239.9
A35: =IF(A34<B$17,A34+1,"") -> 12 | B35: =IF(A35="","",IF(A35<=B$16,"carência","amortização")) -> amortização | C35: =IF(B35="","",E34*$C$23) -> 70.416667 | D35: =IF(C35="","",IF(A35<=B$16,0,B$15/(B$17-B$16))) -> 166.66667 | E35: =IF(F35="","",E34-D35) -> 4000 | F35: =IF(D35="","",D35+C35) -> 237.08333 | AA35: =IF(AA34<B$17,AA34+1,"") -> 6 | AB35: =IF(AA35="","",AB34+30) -> 46420 | AC35: =IF(AB35="","",IF(AA35<=B$16,AC34,AC34-AD35)) -> 5000 | AD35: =IF(AA35="","",IF(AA35<=B$16,0,B$15/(B$17-B$16))) -> 0 | AE35: =IF(AD35="","",AB35-AB34) -> 30 | AF35: =IF(AE35="","",AB35-AB$29) -> 180 | AG35: =IF(AF35="","",IF(AF35<365,AF35*AC$25*AD35,365*AD35*AC$25)) -> 0 | AH35: =IF(AF35="","",IF(AF35<365,AF35*AC$26*AD35,365*AD35*AC$26)) -> 0 | AM35: =F35 -> 237.08333 | AN35: =SUM(F24:F35) -> 1971.75 | AO35: =LARGE(F24:F35,1) -> 251.16667
A36: =IF(A35<B$17,A35+1,"") -> 13 | B36: =IF(A36="","",IF(A36<=B$16,"carência","amortização")) -> amortização | C36: =IF(B36="","",E35*$C$23) -> 67.6 | D36: =IF(C36="","",IF(A36<=B$16,0,E$23/(B$17-B$16))) -> 166.66667 | E36: =IF(F36="","",E35-D36) -> 3833.3333 | F36: =IF(D36="","",D36+C36) -> 234.26667 | AA36: =IF(AA35<B$17,AA35+1,"") -> 7 | AB36: =IF(AA36="","",AB35+30) -> 46450 | AC36: =IF(AB36="","",IF(AA36<=B$16,AC35,AC35-AD36)) -> 4833.3333 | AD36: =IF(AA36="","",IF(AA36<=B$16,0,B$15/(B$17-B$16))) -> 166.66667 | AE36: =IF(AD36="","",AB36-AB35) -> 30 | AF36: =IF(AE36="","",AB36-AB$29) -> 210 | AG36: =IF(AF36="","",IF(AF36<365,AF36*AC$25*AD36,365*AD36*AC$25)) -> 1.435 | AH36: =IF(AF36="","",IF(AF36<365,AF36*AC$26*AD36,365*AD36*AC$26)) -> 0.4795 | AM36: =F36 -> 234.26667
A37: =IF(A36<B$17,A36+1,"") -> 14 | B37: =IF(A37="","",IF(A37<=B$16,"carência","amortização")) -> amortização | C37: =IF(B37="","",E36*$C$23) -> 64.783333 | D37: =IF(C37="","",IF(A37<=B$16,0,E$23/(B$17-B$16))) -> 166.66667 | E37: =IF(F37="","",E36-D37) -> 3666.6667 | F37: =IF(D37="","",D37+C37) -> 231.45 | AA37: =IF(AA36<B$17,AA36+1,"") -> 8 | AB37: =IF(AA37="","",AB36+30) -> 46480 | AC37: =IF(AB37="","",IF(AA37<=B$16,AC36,AC36-AD37)) -> 4666.6667 | AD37: =IF(AA37="","",IF(AA37<=B$16,0,B$15/(B$17-B$16))) -> 166.66667 | AE37: =IF(AD37="","",AB37-AB36) -> 30 | AF37: =IF(AE37="","",AB37-AB$29) -> 240 | AG37: =IF(AF37="","",IF(AF37<365,AF37*AC$25*AD37,365*AD37*AC$25)) -> 1.64 | AH37: =IF(AF37="","",IF(AF37<365,AF37*AC$26*AD37,365*AD37*AC$26)) -> 0.548 | AM37: =F37 -> 231.45
A38: =IF(A37<B$17,A37+1,"") -> 15 | B38: =IF(A38="","",IF(A38<=B$16,"carência","amortização")) -> amortização | C38: =IF(B38="","",E37*$C$23) -> 61.966667 | D38: =IF(C38="","",IF(A38<=B$16,0,E$23/(B$17-B$16))) -> 166.66667 | E38: =IF(F38="","",E37-D38) -> 3500 | F38: =IF(D38="","",D38+C38) -> 228.63333 | AA38: =IF(AA37<B$17,AA37+1,"") -> 9 | AB38: =IF(AA38="","",AB37+30) -> 46510 | AC38: =IF(AB38="","",IF(AA38<=B$16,AC37,AC37-AD38)) -> 4500 | AD38: =IF(AA38="","",IF(AA38<=B$16,0,B$15/(B$17-B$16))) -> 166.66667 | AE38: =IF(AD38="","",AB38-AB37) -> 30 | AF38: =IF(AE38="","",AB38-AB$29) -> 270 | AG38: =IF(AF38="","",IF(AF38<365,AF38*AC$25*AD38,365*AD38*AC$25)) -> 1.845 | AH38: =IF(AF38="","",IF(AF38<365,AF38*AC$26*AD38,365*AD38*AC$26)) -> 0.6165 | AM38: =F38 -> 228.63333
A39: =IF(A38<B$17,A38+1,"") -> 16 | B39: =IF(A39="","",IF(A39<=B$16,"carência","amortização")) -> amortização | C39: =IF(B39="","",E38*$C$23) -> 59.15 | D39: =IF(C39="","",IF(A39<=B$16,0,E$23/(B$17-B$16))) -> 166.66667 | E39: =IF(F39="","",E38-D39) -> 3333.3333 | F39: =IF(D39="","",D39+C39) -> 225.81667 | AA39: =IF(AA38<B$17,AA38+1,"") -> 10 | AB39: =IF(AA39="","",AB38+30) -> 46540 | AC39: =IF(AB39="","",IF(AA39<=B$16,AC38,AC38-AD39)) -> 4333.3333 | AD39: =IF(AA39="","",IF(AA39<=B$16,0,B$15/(B$17-B$16))) -> 166.66667 | AE39: =IF(AD39="","",AB39-AB38) -> 30 | AF39: =IF(AE39="","",AB39-AB$29) -> 300 | AG39: =IF(AF39="","",IF(AF39<365,AF39*AC$25*AD39,365*AD39*AC$25)) -> 2.05 | AH39: =IF(AF39="","",IF(AF39<365,AF39*AC$26*AD39,365*AD39*AC$26)) -> 0.685 | AM39: =F39 -> 225.81667
A40: =IF(A39<B$17,A39+1,"") -> 17 | B40: =IF(A40="","",IF(A40<=B$16,"carência","amortização")) -> amortização | C40: =IF(B40="","",E39*$C$23) -> 56.333333 | D40: =IF(C40="","",IF(A40<=B$16,0,E$23/(B$17-B$16))) -> 166.66667 | E40: =IF(F40="","",E39-D40) -> 3166.6667 | F40: =IF(D40="","",D40+C40) -> 223 | AA40: =IF(AA39<B$17,AA39+1,"") -> 11 | AB40: =IF(AA40="","",AB39+30) -> 46570 | AC40: =IF(AB40="","",IF(AA40<=B$16,AC39,AC39-AD40)) -> 4166.6667 | AD40: =IF(AA40="","",IF(AA40<=B$16,0,B$15/(B$17-B$16))) -> 166.66667 | AE40: =IF(AD40="","",AB40-AB39) -> 30 | AF40: =IF(AE40="","",AB40-AB$29) -> 330 | AG40: =IF(AF40="","",IF(AF40<365,AF40*AC$25*AD40,365*AD40*AC$25)) -> 2.255 | AH40: =IF(AF40="","",IF(AF40<365,AF40*AC$26*AD40,365*AD40*AC$26)) -> 0.7535 | AM40: =F40 -> 223
...

Sheet Mais Crédito (2)
A1: AGÊNCIA DE FOMENTO DE GOIÁS S/A | AA1: 1 | AB1: 1
A2: IMPORTANTE: Os valores simulados podem variar e estão sujeitos à data de vencimento da parcela e da liberação do crédito; O financiamento e condições são sujeitas à aprovação final da análise de crédito; Valores calculados com base na taxa líquida para quando não há atraso nos pagamentos.
A3: LINHA DE CAPITAL DE GIRO/INVESTIMENTO | AA3: TAC | AB3: IOF
A4: LINHA | J4: 1 | K4: 1 | N4: LINHA | O4: TAXA (a.m.) | P4: TAXA BONUS | Q4: CG1 (a.m.) | R4: CG2 (a.m.) | S4: PRAZO (meses) | T4: CARÊNCIA (até meses) | U4: LIMITE | V4: GARANTIA | AA4: Descontado | AB4: Descontado
N5: Mais Crédito Aval do FUNDEQ | O5: 1.69 | P5: 0 | Q5: 1.69 | R5: =Q5 -> 1.69 | S5: 24 | T5: 3 | U5: 21000 | V5: CG1 | AA5: Financiado | AB5: Financiado
C6: =IF(AND(J4=1,K4=1),Q5,IF(AND(J4=1,K4=2),R5,IF(AND(J4=1,K4=3),P5,"-"))) -> 1.69 | N6: Mais CrédIto com parceria - Juro Zero e Aval | O6: 1.69 | P6: 0 | Q6: 0 | R6: 0 | S6: 24 | T6: 3 | U6: 21000 | V6: CG2
C7: =IF(AND(J4=2,K4=1),Q6,IF(AND(J4=2,K4=2),R6,IF(AND(J4=2,K4=3),P6,"-"))) -> - | N7: Mais Crédito Equalização de Juros FUNDEQ | O7: 1.69 | P7: 0 | Q7: 0 | R7: 0 | S7: 24 | T7: 3 | U7: 21000 | V7: NÃO
C8: =IF(AND(J4=3,K4=1),Q7,IF(AND(J4=3,K4=2),R7,IF(AND(J4=3,K4=3),P7,"-"))) -> - | N8: GoiásFomento Giro - VIP IMCF | O8: 1.9 | P8: 0 | Q8: 1.47 | R8: =Q8 -> 1.47 | S8: 36 | T8: 3 | U8: 300000
C9: =IF(AND(J4=4,K4=1),Q8,IF(AND(J4=4,K4=2),R8,IF(AND(J4=4,K4=3),P8,"-"))) -> - | N9: GoiásFomento Giro Consorciado | O9: 1.9 | P9: 0 | Q9: 1.47 | R9: =Q9 -> 1.47 | S9: 36 | T9: 3 | U9: 300000
C10: =IF(AND(J4=5,K4=1),Q9,IF(AND(J4=5,K4=2),R9,IF(AND(J4=5,K4=3),P9,"-"))) -> - | N10: GoiásFomento (GIRO)Tecnologia/PQF-IEL/Turismo/FarmaDrogas/ Contabilistas | O10: 2.05 | P10: 0 | Q10: 1.58 | R10: =Q10 -> 1.58 | S10: 36 | T10: 3 | U10: 300000
C11: =IF(AND(J4=6,K4=1),Q10,IF(AND(J4=6,K4=2),R10,IF(AND(J4=6,K4=3),P10,"-"))) -> - | N11: GoiásFomento Microcrédito Produtivo | O11: 1.82 | P11: 1.5 | Q11: 1.5 | R11: =Q11 -> 1.5 | S11: 36 | T11: 3 | U11: 21000
C12: =IF(AND(J4=7,K4=1),Q11,IF(AND(J4=7,K4=2),R11,IF(AND(J4=7,K4=3),P11,"-"))) -> -
K13: ASSAT1
A14: INFORMAÇÕES | I14: =IF(B15<=5000,IF(AND(B15<=5000,J21=TRUE),D15,0),0.0169) -> 0.0169
A15: VALOR FINANCIADO | B15: 21000 | C15: TAXA NOMINAL | D15: =IF(J4=1,O5,IF(J4=2,O6,IF(J4=3,O7,IF(J4=4,O8,IF(J4=5,O9,IF(J4=6,O10,IF(J4=7,O11)))))))/100 -> 0.0169 | F15: =IF(B15<=3000,50,IF(B15<=21000,IF(B15*0.03<=420,B15*0.03,420),IF(B15<=100000,B15*0.02,2000+B15*0.005))) -> 420 | I15: =IF(B15<=3000,50,IF(B15<=21000,IF(B15*0.03<=420,B15*0.03,420),IF(B15<=100000,B15*0.02,2000+B15*0.005))) -> 420 | J15: 4
A16: CARÊNCIA | B16: 6 | C16: TAXA COM BÔNUS | D16: =IF(B15<=5000,IF(AND(B15<=5000,J21=TRUE),D15,0),0.0169) -> 0.0169 | F16: =AF24 -> 180.2073 | I16: =IF(B15*0.03<=420,B15*0.03,420) -> 420 | J16: 1 | AP16: 36
A17: PRAZO TOTAL | B17: 36 | C17: DATA DA PROPOSTA | D17: =TODAY() -> 46240 | F17: =IF(B15>5000,IF(B15>5000,IF(K4=1,(B15*E19*0.001*B17),IF(K4=2,(F19*0.001*B17),IF(K4=3,0,""))),0),IF(J21=TRUE,IF(K4=1,(B15*E19*0.001*B17),IF(K4=2,(F19*0.001*B17),IF(K4=3,0,""))),0)) -> 756 | J17: Descontado | L17: FALSE
A18: OPÇÕES DE GARANTIA | J18: Financiado
A19: RENDA PARA AVAL | B19: =IF(LARGE(F23:F241,1)*3<2424,2424,LARGE(F23:F241,1)*3) -> 3164.7 | C19: ALIENAÇÃO DE IMÓVEL | D19: =IF(J21=TRUE,(B15-F19)*1.5/0.7,B15*1.5/0.7) -> 0 | E19: 1 | F19: =IF(F17<>0,IF(K4=1,(B15*E19),IF(K4=2,B15*E19,IF(K4=3,0,""))),0) -> 21000 | J19: FINANCIADO | L19: TRUE
A20: SIMULAÇÃO DO VALOR DAS PARCELAS | J20: Financiado | AM20: =IRR(AM23:AM47) -> -0.0059870182
A21: PARCELA | B21: AMORTIZAÇÃO | C21: JUROS | D21: VALOR AMORTIZAÇÃO | E21: SALDO DEVEDOR | F21: PARCELA COM BÔNUS | J21: TRUE | AB21: IOF - ACIMA ATÉ 365 DIAS
A22: TOTAL | C22: =SUM(C23:C242) -> 7630.3669 | D22: =SUM(D23:D242) -> 21000 | F22: =SUM(F23:F242) -> 28630.35
A23: 0 | C23: =D16 -> 0.0169 | E23: =IF(AND(AA1=1,AB1=1,J16=1),B15,IF(AND(AA1=1,AB1=1,J16=2),B15+F17,IF(AND(AA1=1,AB1=2,J16=1),B15+F16,IF(AND(AA1=1,AB1=2,J16=3),B15+F16,IF(AND(AA1=2,AB1=1,J16=1),B15+F15,IF(AND(AA1=2,AB1=1,J16=2),B15+F15+F17,IF(AND(AA1=2,AB1=2,J16=2),B15+F17+F16+F15,IF(AND(AA1=2,AB1=2,J16=3),B15+F15+F16,IF(AND(AA1=2,AB1=2,J16=1),B15+F15+F16,IF(AND(AA1=1,AB1=2,J16=2),B15+F16+F17, IF(AND(AA1=1,AB1=1,J16=3),B15))))))))))) -> 21000 | AM23: =-B15 -> -21000
A24: =IF(A23<B$17,A23+1,"") -> 1 | B24: =IF(A24="","",IF(A24<=B$16,"carência","amortização")) -> carência | C24: =IF(B24="","",E23*$C$23) -> 354.9 | D24: =IF(C24="","",IF(A24<=B$16,0,B$15/(B$17-B$16))) -> 0 | E24: =IF(F24="","",E23-D24) -> 21000 | F24: =IF(D24="","",D24+C24) -> 354.9 | AB24: IOF | AC24: 0.0038 | AE24: =AC27*AC24 -> 79.8 | AF24: =IF(L19=FALSE,0,IF(AND(AH25=TRUE,B15<=30000),AE24+AE26,AE24+AE25)) -> 180.2073 | AM24: =F24 -> 354.9
A25: =IF(A24<B$17,A24+1,"") -> 2 | B25: =IF(A25="","",IF(A25<=B$16,"carência","amortização")) -> carência | C25: =IF(B25="","",E24*$C$23) -> 354.9 | D25: =IF(C25="","",IF(A25<=B$16,0,B$15/(B$17-B$16))) -> 0 | E25: =IF(F25="","",E24-D25) -> 21000 | F25: =IF(D25="","",D25+C25) -> 354.9 | AB25: ALÍQUOTA | AC25: 4.1e-05 | AE25: =SUM(AG30:AG83) -> 300.489 | AH25: TRUE | AM25: =F25 -> 354.9
A26: =IF(A25<B$17,A25+1,"") -> 3 | B26: =IF(A26="","",IF(A26<=B$16,"carência","amortização")) -> carência | C26: =IF(B26="","",E25*$C$23) -> 354.9 | D26: =IF(C26="","",IF(A26<=B$16,0,B$15/(B$17-B$16))) -> 0 | E26: =IF(F26="","",E25-D26) -> 21000 | F26: =IF(D26="","",D26+C26) -> 354.9 | AB26: ALÍQUOTA SIMPLES | AC26: =0.00137/100 -> 1.37e-05 | AE26: =SUM(AH30:AH308) -> 100.4073 | AM26: =F26 -> 354.9
A27: =IF(A26<B$17,A26+1,"") -> 4 | B27: =IF(A27="","",IF(A27<=B$16,"carência","amortização")) -> carência | C27: =IF(B27="","",E26*$C$23) -> 354.9 | D27: =IF(C27="","",IF(A27<=B$16,0,B$15/(B$17-B$16))) -> 0 | E27: =IF(F27="","",E26-D27) -> 21000 | F27: =IF(D27="","",D27+C27) -> 354.9 | AB27: LIBERAÇÃO | AC27: =B15 -> 21000 | AM27: =F27 -> 354.9 | AP27: =F27/0.3 -> 1183 | AQ27: =AP27/0.2 -> 5915 | AS27: =F27/0.2 -> 1774.5 | AU27: 81000
A28: =IF(A27<B$17,A27+1,"") -> 5 | B28: =IF(A28="","",IF(A28<=B$16,"carência","amortização")) -> carência | C28: =IF(B28="","",E27*$C$23) -> 354.9 | D28: =IF(C28="","",IF(A28<=B$16,0,B$15/(B$17-B$16))) -> 0 | E28: =IF(F28="","",E27-D28) -> 21000 | F28: =IF(D28="","",D28+C28) -> 354.9 | AG28: IOF NORMAL | AH28: IOF SIMPLES | AM28: =F28 -> 354.9 | AU28: =AU27/12 -> 6750
A29: =IF(A28<B$17,A28+1,"") -> 6 | B29: =IF(A29="","",IF(A29<=B$16,"carência","amortização")) -> carência | C29: =IF(B29="","",E28*$C$23) -> 354.9 | D29: =IF(C29="","",IF(A29<=B$16,0,B$15/(B$17-B$16))) -> 0 | E29: =IF(F29="","",E28-D29) -> 21000 | F29: =IF(D29="","",D29+C29) -> 354.9 | AA29: 0 | AB29: =D17 -> 46240 | AC29: =IF(AB29="","",AC27) -> 21000 | AD29: =IF(AA29="","",IF(AA29<=B$16,0,B$15/(B$17-B$16))) -> 0 | AM29: =F29 -> 354.9 | AU29: =F27/AU28 -> 0.052577778
